{"data": {"repository": {"pullRequest": {"id": "MDExOlB1bGxSZXF1ZXN0NDk1MjE3NDE5", "number": 2133, "reviewThreads": {"totalCount": 2, "pageInfo": {"startCursor": "Y3Vyc29yOnYyOpK0MjAyMC0wOS0zMFQwNDoyMzo1MVrOEo3UAw==", "endCursor": "Y3Vyc29yOnYyOpK0MjAyMC0wOS0zMFQwNDoyNToxMVrOEo3U4A==", "hasNextPage": false, "hasPreviousPage": false}, "nodes": [{"id": "MDIzOlB1bGxSZXF1ZXN0UmV2aWV3VGhyZWFkMzExMjg0NzM5OnYy", "diffSide": "LEFT", "path": "hudi-common/src/main/java/org/apache/hudi/exception/HoodieIOException.java", "isResolved": true, "comments": {"totalCount": 2, "pageInfo": {"startCursor": "Y3Vyc29yOnYyOpK0MjAyMC0wOS0zMFQwNDoyMzo1MVrOHaM1EA==", "endCursor": "Y3Vyc29yOnYyOpK0MjAyMC0wOS0zMFQwNDozMzoyMVrOHaM9Xg==", "hasNextPage": false, "hasPreviousPage": false}, "nodes": [{"id": "MDI0OlB1bGxSZXF1ZXN0UmV2aWV3Q29tbWVudDQ5NzIzNTIxNg==", "bodyText": "I don't think we should change the semantics of HoodieIOException. The idea is that an IOException is wrapped by hoodie to throw a HoodieIOException. This change gives the false impression by wrapping a generic exception.", "url": "https://github.com/apache/hudi/pull/2133#discussion_r497235216", "createdAt": "2020-09-30T04:23:51Z", "author": {"login": "n3nash"}, "path": "hudi-common/src/main/java/org/apache/hudi/exception/HoodieIOException.java", "diffHunk": "@@ -18,27 +18,25 @@\n \n package org.apache.hudi.exception;\n \n-import java.io.IOException;", "state": "SUBMITTED", "replyTo": null, "originalCommit": {"oid": "f21b06a449ce7f8d99455f951a006fec723a7b43"}, "originalPosition": 4}, {"id": "MDI0OlB1bGxSZXF1ZXN0UmV2aWV3Q29tbWVudDQ5NzIzNzM0Mg==", "bodyText": "make sense", "url": "https://github.com/apache/hudi/pull/2133#discussion_r497237342", "createdAt": "2020-09-30T04:33:21Z", "author": {"login": "lw309637554"}, "path": "hudi-common/src/main/java/org/apache/hudi/exception/HoodieIOException.java", "diffHunk": "@@ -18,27 +18,25 @@\n \n package org.apache.hudi.exception;\n \n-import java.io.IOException;", "state": "SUBMITTED", "replyTo": {"id": "MDI0OlB1bGxSZXF1ZXN0UmV2aWV3Q29tbWVudDQ5NzIzNTIxNg=="}, "originalCommit": {"oid": "f21b06a449ce7f8d99455f951a006fec723a7b43"}, "originalPosition": 4}]}}, {"id": "MDIzOlB1bGxSZXF1ZXN0UmV2aWV3VGhyZWFkMzExMjg0OTYwOnYy", "diffSide": "RIGHT", "path": "hudi-common/src/main/java/org/apache/hudi/common/table/log/AbstractHoodieLogRecordScanner.java", "isResolved": true, "comments": {"totalCount": 3, "pageInfo": {"startCursor": "Y3Vyc29yOnYyOpK0MjAyMC0wOS0zMFQwNDoyNToxMVrOHaM2WQ==", "endCursor": "Y3Vyc29yOnYyOpK0MjAyMC0wOS0zMFQwNzoxMzoyOVrOHaQJkg==", "hasNextPage": false, "hasPreviousPage": false}, "nodes": [{"id": "MDI0OlB1bGxSZXF1ZXN0UmV2aWV3Q29tbWVudDQ5NzIzNTU0NQ==", "bodyText": "@lw309637554 Can you check if the catch (Exception e) can be changed to catch (IOException io) ? If not that we are not just catching IOException but also other exceptions and then we should add appropriate multiple catch blocks and throw the correct exception.", "url": "https://github.com/apache/hudi/pull/2133#discussion_r497235545", "createdAt": "2020-09-30T04:25:11Z", "author": {"login": "n3nash"}, "path": "hudi-common/src/main/java/org/apache/hudi/common/table/log/AbstractHoodieLogRecordScanner.java", "diffHunk": "@@ -244,7 +244,7 @@ public void scan() {\n       progress = 1.0f;\n     } catch (Exception e) {\n       LOG.error(\"Got exception when reading log file\", e);\n-      throw new HoodieIOException(\"IOException when reading log file \");\n+      throw new HoodieIOException(\"IOException when reading log file \", e);", "state": "SUBMITTED", "replyTo": null, "originalCommit": {"oid": "f21b06a449ce7f8d99455f951a006fec723a7b43"}, "originalPosition": 5}, {"id": "MDI0OlB1bGxSZXF1ZXN0UmV2aWV3Q29tbWVudDQ5NzIzNzM4MQ==", "bodyText": "ok , i will see it.", "url": "https://github.com/apache/hudi/pull/2133#discussion_r497237381", "createdAt": "2020-09-30T04:33:32Z", "author": {"login": "lw309637554"}, "path": "hudi-common/src/main/java/org/apache/hudi/common/table/log/AbstractHoodieLogRecordScanner.java", "diffHunk": "@@ -244,7 +244,7 @@ public void scan() {\n       progress = 1.0f;\n     } catch (Exception e) {\n       LOG.error(\"Got exception when reading log file\", e);\n-      throw new HoodieIOException(\"IOException when reading log file \");\n+      throw new HoodieIOException(\"IOException when reading log file \", e);", "state": "SUBMITTED", "replyTo": {"id": "MDI0OlB1bGxSZXF1ZXN0UmV2aWV3Q29tbWVudDQ5NzIzNTU0NQ=="}, "originalCommit": {"oid": "f21b06a449ce7f8d99455f951a006fec723a7b43"}, "originalPosition": 5}, {"id": "MDI0OlB1bGxSZXF1ZXN0UmV2aWV3Q29tbWVudDQ5NzI4OTYxOA==", "bodyText": "can not change to IOException, because in processQueuedBlocksForInstant , the implement for LogRecordScannerCallback will throw InterruptedException exception, may be other implement throw other exception.\npublic static interface LogRecordScannerCallback {\npublic void apply(HoodieRecord<? extends HoodieRecordPayload> record) throws Exception;\n\n}.\nso , i think can catch also IOException wrap HoodieIOException and Exception wrap HoodieException", "url": "https://github.com/apache/hudi/pull/2133#discussion_r497289618", "createdAt": "2020-09-30T07:13:29Z", "author": {"login": "lw309637554"}, "path": "hudi-common/src/main/java/org/apache/hudi/common/table/log/AbstractHoodieLogRecordScanner.java", "diffHunk": "@@ -244,7 +244,7 @@ public void scan() {\n       progress = 1.0f;\n     } catch (Exception e) {\n       LOG.error(\"Got exception when reading log file\", e);\n-      throw new HoodieIOException(\"IOException when reading log file \");\n+      throw new HoodieIOException(\"IOException when reading log file \", e);", "state": "SUBMITTED", "replyTo": {"id": "MDI0OlB1bGxSZXF1ZXN0UmV2aWV3Q29tbWVudDQ5NzIzNTU0NQ=="}, "originalCommit": {"oid": "f21b06a449ce7f8d99455f951a006fec723a7b43"}, "originalPosition": 5}]}}]}}}, "rateLimit": {"limit": 5000, "remaining": 4317, "cost": 1, "resetAt": "2021-11-12T09:44:50Z"}}}